Workbook

Sheet Analysis
A1: season | B1: player_id | C1: player | D1: salary | E1: Games | F1: PPG | G1: RPG | H1: APG | I1: SPG | J1: BPG | K1: MPG | L1: Total_Points | M1: Total_Rebounds | N1: Total_Assists | O1: Total_Steals | P1: Total_Blocks | Q1: Total_Minutes | R1: Combined_VORP | S1: VORP_per_$1M | T1: Combined_VORP_Graph | U1: Salary_Graph | V1: Predicted_Salary | W1: Salary_Residual
C2: Zyon Pullin | D2: =SUMIF('Salary Data'!C:C,C2,'Salary Data'!D:D) -> 223637 | E2: =_xlfn.XLOOKUP(C2,'Player Stats'!A:A,'Player Stats'!B:B,0) -> 5 | F2: =_xlfn.XLOOKUP(C2,'Player Stats'!A:A,'Player Stats'!C:C,0) -> 4.6 | G2: =_xlfn.XLOOKUP(C2,'Player Stats'!A:A,'Player Stats'!D:D,0) -> 0.6 | H2: =_xlfn.XLOOKUP(C2,'Player Stats'!A:A,'Player Stats'!E:E,0) -> 1.8 | I2: =_xlfn.XLOOKUP(C2,'Player Stats'!A:A,'Player Stats'!F:F,0) -> 0.2 | J2: =_xlfn.XLOOKUP(C2,'Player Stats'!A:A,'Player Stats'!G:G,0) -> 0 | K2: =_xlfn.XLOOKUP(C2,'Player Stats'!A:A,'Player Stats'!H:H,0) -> 8.5166667 | L2: =E2*F2 -> 23 | M2: =E2*G2 -> 3 | N2: =E2*H2 -> 9 | O2: =E2*I2 -> 1 | P2: =E2*J2 -> 0 | Q2: =E2*K2 -> 42.583333 | R2: =_xlfn.XLOOKUP(C2,'VORP Data'!$B:$B, 'VORP Data'!$E:$E,0) -> 0 | S2: =R2/(D2/1000000) -> 0 | T2: =IF(AND(E2>=40,K2>=20),R2,NA()) -> #N/A | U2: =IF(AND(E2>=40,K2>=20),D2,NA()) -> #N/A | V2: =IF(AND(E2>=40,K2>=20),9997988.56+4996076.47*R2,NA()) -> #N/A | W2: =D2-V2 -> #N/A
C3: Zeke Nnaji | D3: =SUMIF('Salary Data'!C:C,C3,'Salary Data'!D:D) -> 8177778 | E3: =_xlfn.XLOOKUP(C3,'Player Stats'!A:A,'Player Stats'!B:B,0) -> 54 | F3: =_xlfn.XLOOKUP(C3,'Player Stats'!A:A,'Player Stats'!C:C,0) -> 3.7037037 | G3: =_xlfn.XLOOKUP(C3,'Player Stats'!A:A,'Player Stats'!D:D,0) -> 2.5740741 | H3: =_xlfn.XLOOKUP(C3,'Player Stats'!A:A,'Player Stats'!E:E,0) -> 0.55555556 | I3: =_xlfn.XLOOKUP(C3,'Player Stats'!A:A,'Player Stats'!F:F,0) -> 0.33333333 | J3: =_xlfn.XLOOKUP(C3,'Player Stats'!A:A,'Player Stats'!G:G,0) -> 0.44444444 | K3: =_xlfn.XLOOKUP(C3,'Player Stats'!A:A,'Player Stats'!H:H,0) -> 11.945988 | L3: =E3*F3 -> 200 | M3: =E3*G3 -> 139 | N3: =E3*H3 -> 30 | O3: =E3*I3 -> 18 | P3: =E3*J3 -> 24 | Q3: =E3*K3 -> 645.08333 | R3: =_xlfn.XLOOKUP(C3,'VORP Data'!$B:$B, 'VORP Data'!$E:$E,0) -> -0.2 | S3: =R3/(D3/1000000) -> -0.024456521 | T3: =IF(AND(E3>=40,K3>=20),R3,NA()) -> #N/A | U3: =IF(AND(E3>=40,K3>=20),D3,NA()) -> #N/A | V3: =IF(AND(E3>=40,K3>=20),9997988.56+4996076.47*R3,NA()) -> #N/A | W3: =D3-V3 -> #N/A
C4: Zach LaVine | D4: =SUMIF('Salary Data'!C:C,C4,'Salary Data'!D:D) -> 47499660 | E4: =_xlfn.XLOOKUP(C4,'Player Stats'!A:A,'Player Stats'!B:B,0) -> 39 | F4: =_xlfn.XLOOKUP(C4,'Player Stats'!A:A,'Player Stats'!C:C,0) -> 19.179487 | G4: =_xlfn.XLOOKUP(C4,'Player Stats'!A:A,'Player Stats'!D:D,0) -> 2.7692308 | H4: =_xlfn.XLOOKUP(C4,'Player Stats'!A:A,'Player Stats'!E:E,0) -> 2.2820513 | I4: =_xlfn.XLOOKUP(C4,'Player Stats'!A:A,'Player Stats'!F:F,0) -> 0.71794872 | J4: =_xlfn.XLOOKUP(C4,'Player Stats'!A:A,'Player Stats'!G:G,0) -> 0.25641026 | K4: =_xlfn.XLOOKUP(C4,'Player Stats'!A:A,'Player Stats'!H:H,0) -> 31.391453 | L4: =E4*F4 -> 748 | M4: =E4*G4 -> 108 | N4: =E4*H4 -> 89 | O4: =E4*I4 -> 28 | P4: =E4*J4 -> 10 | Q4: =E4*K4 -> 1224.2667 | R4: =_xlfn.XLOOKUP(C4,'VORP Data'!$B:$B, 'VORP Data'!$E:$E,0) -> 0.2 | S4: =R4/(D4/1000000) -> 0.0042105565 | T4: =IF(AND(E4>=40,K4>=20),R4,NA()) -> #N/A | U4: =IF(AND(E4>=40,K4>=20),D4,NA()) -> #N/A | V4: =IF(AND(E4>=40,K4>=20),9997988.56+4996076.47*R4,NA()) -> #N/A | W4: =D4-V4 -> #N/A
C5: Zach Edey | D5: =SUMIF('Salary Data'!C:C,C5,'Salary Data'!D:D) -> 6045000 | E5: =_xlfn.XLOOKUP(C5,'Player Stats'!A:A,'Player Stats'!B:B,0) -> 11 | F5: =_xlfn.XLOOKUP(C5,'Player Stats'!A:A,'Player Stats'!C:C,0) -> 13.636364 | G5: =_xlfn.XLOOKUP(C5,'Player Stats'!A:A,'Player Stats'!D:D,0) -> 11.090909 | H5: =_xlfn.XLOOKUP(C5,'Player Stats'!A:A,'Player Stats'!E:E,0) -> 1.0909091 | I5: =_xlfn.XLOOKUP(C5,'Player Stats'!A:A,'Player Stats'!F:F,0) -> 0.63636364 | J5: =_xlfn.XLOOKUP(C5,'Player Stats'!A:A,'Player Stats'!G:G,0) -> 1.9090909 | K5: =_xlfn.XLOOKUP(C5,'Player Stats'!A:A,'Player Stats'!H:H,0) -> 25.804545 | L5: =E5*F5 -> 150 | M5: =E5*G5 -> 122 | N5: =E5*H5 -> 12 | O5: =E5*I5 -> 7 | P5: =E5*J5 -> 21 | Q5: =E5*K5 -> 283.85 | R5: =_xlfn.XLOOKUP(C5,'VORP Data'!$B:$B, 'VORP Data'!$E:$E,0) -> 0.2 | S5: =R5/(D5/1000000) -> 0.033085194 | T5: =IF(AND(E5>=40,K5>=20),R5,NA()) -> #N/A | U5: =IF(AND(E5>=40,K5>=20),D5,NA()) -> #N/A | V5: =IF(AND(E5>=40,K5>=20),9997988.56+4996076.47*R5,NA()) -> #N/A | W5: =D5-V5 -> #N/A
C6: Zach Collins | D6: =SUMIF('Salary Data'!C:C,C6,'Salary Data'!D:D) -> 18080496 | E6: =_xlfn.XLOOKUP(C6,'Player Stats'!A:A,'Player Stats'!B:B,0) -> 10 | F6: =_xlfn.XLOOKUP(C6,'Player Stats'!A:A,'Player Stats'!C:C,0) -> 9.7 | G6: =_xlfn.XLOOKUP(C6,'Player Stats'!A:A,'Player Stats'!D:D,0) -> 5.6 | H6: =_xlfn.XLOOKUP(C6,'Player Stats'!A:A,'Player Stats'!E:E,0) -> 1.5 | I6: =_xlfn.XLOOKUP(C6,'Player Stats'!A:A,'Player Stats'!F:F,0) -> 0.2 | J6: =_xlfn.XLOOKUP(C6,'Player Stats'!A:A,'Player Stats'!G:G,0) -> 0.4 | K6: =_xlfn.XLOOKUP(C6,'Player Stats'!A:A,'Player Stats'!H:H,0) -> 18.373333 | L6: =E6*F6 -> 97 | M6: =E6*G6 -> 56 | N6: =E6*H6 -> 15 | O6: =E6*I6 -> 2 | P6: =E6*J6 -> 4 | Q6: =E6*K6 -> 183.73333 | R6: =_xlfn.XLOOKUP(C6,'VORP Data'!$B:$B, 'VORP Data'!$E:$E,0) -> 0.1 | S6: =R6/(D6/1000000) -> 0.0055308217 | T6: =IF(AND(E6>=40,K6>=20),R6,NA()) -> #N/A | U6: =IF(AND(E6>=40,K6>=20),D6,NA()) -> #N/A | V6: =IF(AND(E6>=40,K6>=20),9997988.56+4996076.47*R6,NA()) -> #N/A | W6: =D6-V6 -> #N/A
C7: Yves Missi | D7: =SUMIF('Salary Data'!C:C,C7,'Salary Data'!D:D) -> 3353040 | E7: =_xlfn.XLOOKUP(C7,'Player Stats'!A:A,'Player Stats'!B:B,0) -> 66 | F7: =_xlfn.XLOOKUP(C7,'Player Stats'!A:A,'Player Stats'!C:C,0) -> 5.7121212 | G7: =_xlfn.XLOOKUP(C7,'Player Stats'!A:A,'Player Stats'!D:D,0) -> 5.8333333 | H7: =_xlfn.XLOOKUP(C7,'Player Stats'!A:A,'Player Stats'!E:E,0) -> 1.2727273 | I7: =_xlfn.XLOOKUP(C7,'Player Stats'!A:A,'Player Stats'!F:F,0) -> 0.3030303 | J7: =_xlfn.XLOOKUP(C7,'Player Stats'!A:A,'Player Stats'!G:G,0) -> 1.530303 | K7: =_xlfn.XLOOKUP(C7,'Player Stats'!A:A,'Player Stats'!H:H,0) -> 19.65202 | L7: =E7*F7 -> 377 | M7: =E7*G7 -> 385 | N7: =E7*H7 -> 84 | O7: =E7*I7 -> 20 | P7: =E7*J7 -> 101 | Q7: =E7*K7 -> 1297.0333 | R7: =_xlfn.XLOOKUP(C7,'VORP Data'!$B:$B, 'VORP Data'!$E:$E,0) -> 0.1 | S7: =R7/(D7/1000000) -> 0.029823682 | T7: =IF(AND(E7>=40,K7>=20),R7,NA()) -> #N/A | U7: =IF(AND(E7>=40,K7>=20),D7,NA()) -> #N/A | V7: =IF(AND(E7>=40,K7>=20),9997988.56+4996076.47*R7,NA()) -> #N/A | W7: =D7-V7 -> #N/A
C8: Yuki Kawamura | D8: =SUMIF('Salary Data'!C:C,C8,'Salary Data'!D:D) -> 312062 | E8: =_xlfn.XLOOKUP(C8,'Player Stats'!A:A,'Player Stats'!B:B,0) -> 18 | F8: =_xlfn.XLOOKUP(C8,'Player Stats'!A:A,'Player Stats'!C:C,0) -> 3.4444444 | G8: =_xlfn.XLOOKUP(C8,'Player Stats'!A:A,'Player Stats'!D:D,0) -> 1.8333333 | H8: =_xlfn.XLOOKUP(C8,'Player Stats'!A:A,'Player Stats'!E:E,0) -> 2.6111111 | I8: =_xlfn.XLOOKUP(C8,'Player Stats'!A:A,'Player Stats'!F:F,0) -> 0.5 | J8: =_xlfn.XLOOKUP(C8,'Player Stats'!A:A,'Player Stats'!G:G,0) -> 0 | K8: =_xlfn.XLOOKUP(C8,'Player Stats'!A:A,'Player Stats'!H:H,0) -> 11.612963 | L8: =E8*F8 -> 62 | M8: =E8*G8 -> 33 | N8: =E8*H8 -> 47 | O8: =E8*I8 -> 9 | P8: =E8*J8 -> 0 | Q8: =E8*K8 -> 209.03333 | R8: =_xlfn.XLOOKUP(C8,'VORP Data'!$B:$B, 'VORP Data'!$E:$E,0) -> -0.1 | S8: =R8/(D8/1000000) -> -0.32044914 | T8: =IF(AND(E8>=40,K8>=20),R8,NA()) -> #N/A | U8: =IF(AND(E8>=40,K8>=20),D8,NA()) -> #N/A | V8: =IF(AND(E8>=40,K8>=20),9997988.56+4996076.47*R8,NA()) -> #N/A | W8: =D8-V8 -> #N/A
C9: Yanic Konan Niederhauser | D9: =SUMIF('Salary Data'!C:C,C9,'Salary Data'!D:D) -> 2743800 | E9: =_xlfn.XLOOKUP(C9,'Player Stats'!A:A,'Player Stats'!B:B,0) -> 41 | F9: =_xlfn.XLOOKUP(C9,'Player Stats'!A:A,'Player Stats'!C:C,0) -> 4.2926829 | G9: =_xlfn.XLOOKUP(C9,'Player Stats'!A:A,'Player Stats'!D:D,0) -> 2.8536585 | H9: =_xlfn.XLOOKUP(C9,'Player Stats'!A:A,'Player Stats'!E:E,0) -> 0.29268293 | I9: =_xlfn.XLOOKUP(C9,'Player Stats'!A:A,'Player Stats'!F:F,0) -> 0.12195122 | J9: =_xlfn.XLOOKUP(C9,'Player Stats'!A:A,'Player Stats'!G:G,0) -> 0.73170732 | K9: =_xlfn.XLOOKUP(C9,'Player Stats'!A:A,'Player Stats'!H:H,0) -> 10.333333 | L9: =E9*F9 -> 176 | M9: =E9*G9 -> 117 | N9: =E9*H9 -> 12 | O9: =E9*I9 -> 5 | P9: =E9*J9 -> 30 | Q9: =E9*K9 -> 423.66667 | R9: =_xlfn.XLOOKUP(C9,'VORP Data'!$B:$B, 'VORP Data'!$E:$E,0) -> 0 | S9: =R9/(D9/1000000) -> 0 | T9: =IF(AND(E9>=40,K9>=20),R9,NA()) -> #N/A | U9: =IF(AND(E9>=40,K9>=20),D9,NA()) -> #N/A | V9: =IF(AND(E9>=40,K9>=20),9997988.56+4996076.47*R9,NA()) -> #N/A | W9: =D9-V9 -> #N/A
C10: Xavier Tillman Sr. | D10: =SUMIF('Salary Data'!C:C,C10,'Salary Data'!D:D) -> 2546675 | E10: =_xlfn.XLOOKUP(C10,'Player Stats'!A:A,'Player Stats'!B:B,0) -> 31 | F10: =_xlfn.XLOOKUP(C10,'Player Stats'!A:A,'Player Stats'!C:C,0) -> 1.483871 | G10: =_xlfn.XLOOKUP(C10,'Player Stats'!A:A,'Player Stats'!D:D,0) -> 1.4516129 | H10: =_xlfn.XLOOKUP(C10,'Player Stats'!A:A,'Player Stats'!E:E,0) -> 0.41935484 | I10: =_xlfn.XLOOKUP(C10,'Player Stats'!A:A,'Player Stats'!F:F,0) -> 0.29032258 | J10: =_xlfn.XLOOKUP(C10,'Player Stats'!A:A,'Player Stats'!G:G,0) -> 0.16129032 | K10: =_xlfn.XLOOKUP(C10,'Player Stats'!A:A,'Player Stats'!H:H,0) -> 6.1451613 | L10: =E10*F10 -> 46 | M10: =E10*G10 -> 45 | N10: =E10*H10 -> 13 | O10: =E10*I10 -> 9 | P10: =E10*J10 -> 5 | Q10: =E10*K10 -> 190.5 | R10: =_xlfn.XLOOKUP(C10,'VORP Data'!$B:$B, 'VORP Data'!$E:$E,0) -> 0 | S10: =R10/(D10/1000000) -> 0 | T10: =IF(AND(E10>=40,K10>=20),R10,NA()) -> #N/A | U10: =IF(AND(E10>=40,K10>=20),D10,NA()) -> #N/A | V10: =IF(AND(E10>=40,K10>=20),9997988.56+4996076.47*R10,NA()) -> #N/A | W10: =D10-V10 -> #N/A
C11: Will Richard | D11: =SUMIF('Salary Data'!C:C,C11,'Salary Data'!D:D) -> 1272870 | E11: =_xlfn.XLOOKUP(C11,'Player Stats'!A:A,'Player Stats'!B:B,0) -> 70 | F11: =_xlfn.XLOOKUP(C11,'Player Stats'!A:A,'Player Stats'!C:C,0) -> 6.3 | G11: =_xlfn.XLOOKUP(C11,'Player Stats'!A:A,'Player Stats'!D:D,0) -> 2.4571429 | H11: =_xlfn.XLOOKUP(C11,'Player Stats'!A:A,'Player Stats'!E:E,0) -> 1.3285714 | I11: =_xlfn.XLOOKUP(C11,'Player Stats'!A:A,'Player Stats'!F:F,0) -> 1.1428571 | J11: =_xlfn.XLOOKUP(C11,'Player Stats'!A:A,'Player Stats'!G:G,0) -> 0.12857143 | K11: =_xlfn.XLOOKUP(C11,'Player Stats'!A:A,'Player Stats'!H:H,0) -> 19.684524 | L11: =E11*F11 -> 441 | M11: =E11*G11 -> 172 | N11: =E11*H11 -> 93 | O11: =E11*I11 -> 80 | P11: =E11*J11 -> 9 | Q11: =E11*K11 -> 1377.9167 | R11: =_xlfn.XLOOKUP(C11,'VORP Data'!$B:$B, 'VORP Data'!$E:$E,0) -> 0.1 | S11: =R11/(D11/1000000) -> 0.078562618 | T11: =IF(AND(E11>=40,K11>=20),R11,NA()) -> #N/A | U11: =IF(AND(E11>=40,K11>=20),D11,NA()) -> #N/A | V11: =IF(AND(E11>=40,K11>=20),9997988.56+4996076.47*R11,NA()) -> #N/A | W11: =D11-V11 -> #N/A
C12: Wendell Moore Jr. | D12: =SUMIF('Salary Data'!C:C,C12,'Salary Data'!D:D) -> 495439 | E12: =_xlfn.XLOOKUP(C12,'Player Stats'!A:A,'Player Stats'!B:B,0) -> 6 | F12: =_xlfn.XLOOKUP(C12,'Player Stats'!A:A,'Player Stats'!C:C,0) -> 1.6666667 | G12: =_xlfn.XLOOKUP(C12,'Player Stats'!A:A,'Player Stats'!D:D,0) -> 1 | H12: =_xlfn.XLOOKUP(C12,'Player Stats'!A:A,'Player Stats'!E:E,0) -> 0.66666667 | I12: =_xlfn.XLOOKUP(C12,'Player Stats'!A:A,'Player Stats'!F:F,0) -> 0.33333333 | J12: =_xlfn.XLOOKUP(C12,'Player Stats'!A:A,'Player Stats'!G:G,0) -> 0.33333333 | K12: =_xlfn.XLOOKUP(C12,'Player Stats'!A:A,'Player Stats'!H:H,0) -> 9.925 | L12: =E12*F12 -> 10 | M12: =E12*G12 -> 6 | N12: =E12*H12 -> 4 | O12: =E12*I12 -> 2 | P12: =E12*J12 -> 2 | Q12: =E12*K12 -> 59.55 | R12: =_xlfn.XLOOKUP(C12,'VORP Data'!$B:$B, 'VORP Data'!$E:$E,0) -> 0 | S12: =R12/(D12/1000000) -> 0 | T12: =IF(AND(E12>=40,K12>=20),R12,NA()) -> #N/A | U12: =IF(AND(E12>=40,K12>=20),D12,NA()) -> #N/A | V12: =IF(AND(E12>=40,K12>=20),9997988.56+4996076.47*R12,NA()) -> #N/A | W12: =D12-V12 -> #N/A
C13: Walker Kessler | D13: =SUMIF('Salary Data'!C:C,C13,'Salary Data'!D:D) -> 4878938 | E13: =_xlfn.XLOOKUP(C13,'Player Stats'!A:A,'Player Stats'!B:B,0) -> 5 | F13: =_xlfn.XLOOKUP(C13,'Player Stats'!A:A,'Player Stats'!C:C,0) -> 14.4 | G13: =_xlfn.XLOOKUP(C13,'Player Stats'!A:A,'Player Stats'!D:D,0) -> 10.8 | H13: =_xlfn.XLOOKUP(C13,'Player Stats'!A:A,'Player Stats'!E:E,0) -> 3 | I13: =_xlfn.XLOOKUP(C13,'Player Stats'!A:A,'Player Stats'!F:F,0) -> 1.4 | J13: =_xlfn.XLOOKUP(C13,'Player Stats'!A:A,'Player Stats'!G:G,0) -> 1.8 | K13: =_xlfn.XLOOKUP(C13,'Player Stats'!A:A,'Player Stats'!H:H,0) -> 30.796667 | L13: =E13*F13 -> 72 | M13: =E13*G13 -> 54 | N13: =E13*H13 -> 15 | O13: =E13*I13 -> 7 | P13: =E13*J13 -> 9 | Q13: =E13*K13 -> 153.98333 | R13: =_xlfn.XLOOKUP(C13,'VORP Data'!$B:$B, 'VORP Data'!$E:$E,0) -> 0.2 | S13: =R13/(D13/1000000) -> 0.040992527 | T13: =IF(AND(E13>=40,K13>=20),R13,NA()) -> #N/A | U13: =IF(AND(E13>=40,K13>=20),D13,NA()) -> #N/A | V13: =IF(AND(E13>=40,K13>=20),9997988.56+4996076.47*R13,NA()) -> #N/A | W13: =D13-V13 -> #N/A
... C594: Stephen Curry | D594: =SUMIF('Salary Data'!C:C,C594,'Salary Data'!D:D) -> 59606817 | E594: =_xlfn.XLOOKUP(C594,'Player Stats'!A:A,'Player Stats'!B:B,0) -> 45 | F594: =_xlfn.XLOOKUP(C594,'Player Stats'!A:A,'Player Stats'!C:C,0) -> 26.533333 | G594: =_xlfn.XLOOKUP(C594,'Player Stats'!A:A,'Player Stats'!D:D,0) -> 3.5333333 | H594: =_xlfn.XLOOKUP(C594,'Player Stats'!A:A,'Player Stats'!E:E,0) -> 4.6888889 | I594: =_xlfn.XLOOKUP(C594,'Player Stats'!A:A,'Player Stats'!F:F,0) -> 1.1555556 | J594: =_xlfn.XLOOKUP(C594,'Player Stats'!A:A,'Player Stats'!G:G,0) -> 0.37777778 | K594: =_xlfn.XLOOKUP(C594,'Player Stats'!A:A,'Player Stats'!H:H,0) -> 31.124074 | L594: =E594*F594 -> 1194 | M594: =E594*G594 -> 159 | N594: =E594*H594 -> 211 | O594: =E594*I594 -> 52 | P594: =E594*J594 -> 17 | Q594: =E594*K594 -> 1400.5833 | R594: =_xlfn.XLOOKUP(C594,'VORP Data'!$B:$B, 'VORP Data'!$E:$E,0) -> 2.5 | S594: =R594/(D594/1000000) -> 0.041941511 | T594: =IF(AND(E594>=40,K594>=20),R594,NA()) -> 2.5 | U594: =IF(AND(E594>=40,K594>=20),D594,NA()) -> 59606817 | V594: =IF(AND(E594>=40,K594>=20),9997988.56+4996076.47*R594,NA()) -> 22488180 | W594: =D594-V594 -> 37118637

Sheet Charts
L1: player | M1: VORP_per_$1M
L2: Collin Gillespie | M2: 1.1349927
L3: Julian Champagnie | M3: 1.0333333
L4: Javon Small | M4: 0.94275142
L5: Sandro Mamukelashvili | M5: 0.85315115
L6: Jordan Miller | M6: 0.72601211
L7: Cam Spencer | M7: 0.70922293
L8: Ryan Kalkbrenner | M8: 0.60968334
L9: Victor Wembanyama | M9: 0.59805505
L10: Ajay Mitchell | M10: 0.56666667
L11: Jalen Duren | M11: 0.53986152

Sheet Player Stats
A3: Player | B3: Games | C3: PPG | D3: RPG | E3: APG | F3: SPG | G3: BPG | H3: Average of MP_decimal
A4: A.J. Green | B4: 78 | C4: 10.371795 | D4: 2.7307692 | E4: 1.9487179 | F4: 0.5 | G4: 0.1025641 | H4: 29.101923
A5: A.J. Lawson | B5: 31 | C5: 3.6451613 | D5: 1.483871 | E5: 0.35483871 | F5: 0.38709677 | G5: 0.19354839 | H5: 8.9263441
A6: Aaron Gordon | B6: 39 | C6: 15.794872 | D6: 5.7692308 | E6: 2.6410256 | F6: 0.53846154 | G6: 0.28205128 | H6: 28.058974
A7: Aaron Holiday | B7: 63 | C7: 5.2063492 | D7: 0.95238095 | E7: 1 | F7: 0.46031746 | G7: 0.095238095 | H7: 13.452116
A8: Aaron Nesmith | B8: 45 | C8: 13.8 | D8: 4.1555556 | E8: 1.9111111 | F8: 0.57777778 | G8: 0.51111111 | H8: 29.665185
A9: Aaron Wiggins | B9: 78 | C9: 8.0769231 | D9: 2.6153846 | E9: 1.4615385 | F9: 0.78205128 | G9: 0.37179487 | H9: 19.093803
A10: Ace Bailey | B10: 72 | C10: 13.791667 | D10: 4.1944444 | E10: 1.8194444 | F10: 0.83333333 | G10: 0.68055556 | H10: 27.606713
A11: Adama-Alpha Bal | B11: 8 | C11: 10.375 | D11: 3.125 | E11: 2.375 | F11: 1.125 | G11: 0.125 | H11: 30.164583
A12: Adem Bona | B12: 82 | C12: 4.5365854 | D12: 4.0365854 | E12: 0.40243902 | F12: 0.37804878 | G12: 1.1219512 | H12: 16.414024
A13: Adou Thiero | B13: 31 | C13: 1.8064516 | D13: 1.2903226 | E13: 0.35483871 | F13: 0.22580645 | G13: 0.064516129 | H13: 5.8854839
A14: AJ Johnson | B14: 48 | C14: 3.3333333 | D14: 1.1458333 | E14: 0.97916667 | F14: 0.22916667 | G14: 0.0625 | H14: 9.4465278
A15: Ajay Mitchell | B15: 68 | C15: 13.823529 | D15: 3.3970588 | E15: 3.7205882 | F15: 1.2941176 | G15: 0.27941176 | H15: 26.316422
... A586: Grand Total | B586: 28716 | C586: 10.597855 | D586: 4.0220783 | E586: 2.4410085 | F586: 0.77284441 | G586: 0.44779914 | H586: 22.218127

Sheet Salary Data
A1: season | B1: player_id | C1: player | D1: salary | E1: team | F1: Games | G1: PPG | H1: RPG | I1: APG | J1: SPG | K1: BPG | L1: MPG | M1: Total_Points | N1: Total_Rebounds | O1: Total_Assists | P1: Total_Steals | Q1: Total_Blocks | R1: Total_Minutes | S1: Points_per_$1M | T1: Rebounds_per_$1M | U1: Assist_per_$1M | V1: Steals_per_$1M | W1: Blocks_per_$1M | X1: Qualified
A2: 2025-26 | B2: 1132825 | C2: Tyrese Haliburton | D2: 45550512 | E2: Indiana Pacers | F2: =_xlfn.XLOOKUP(C2,'Player Stats'!A:A,'Player Stats'!B:B) -> #N/A | G2: =_xlfn.XLOOKUP(C2,'Player Stats'!A:A,'Player Stats'!C:C) -> #N/A | H2: =_xlfn.XLOOKUP(C2,'Player Stats'!A:A,'Player Stats'!D:D) -> #N/A | I2: =_xlfn.XLOOKUP(C2,'Player Stats'!A:A,'Player Stats'!E:E) -> #N/A | J2: =_xlfn.XLOOKUP(C2,'Player Stats'!A:A,'Player Stats'!F:F) -> #N/A | K2: =_xlfn.XLOOKUP(C2,'Player Stats'!A:A,'Player Stats'!G:G) -> #N/A | L2: =_xlfn.XLOOKUP(C2,'Player Stats'!A:A,'Player Stats'!H:H) -> #N/A | M2: =F2*G2 -> #N/A | N2: =F2*H2 -> #N/A | O2: =F2*I2 -> #N/A | P2: =F2*J2 -> #N/A | Q2: =F2*K2 -> #N/A | R2: =F2*L2 -> #N/A | S2: =(M2/D2)*1000000 -> #N/A | T2: =(N2/D2)*1000000 -> #N/A | U2: =(O2/D2)*1000000 -> #N/A | V2: =(P2/D2)*1000000 -> #N/A | W2: =(Q2/D2)*1000000 -> #N/A | X2: =IF(AND(F2>=20,L2>=15),"Yes","No") -> #N/A
A3: 2025-26 | B3: 942843 | C3: Jay Huff | D3: 2349578 | E3: Indiana Pacers | F3: =_xlfn.XLOOKUP(C3,'Player Stats'!A:A,'Player Stats'!B:B) -> 82 | G3: =_xlfn.XLOOKUP(C3,'Player Stats'!A:A,'Player Stats'!C:C) -> 9.5487805 | H3: =_xlfn.XLOOKUP(C3,'Player Stats'!A:A,'Player Stats'!D:D) -> 3.9512195 | I3: =_xlfn.XLOOKUP(C3,'Player Stats'!A:A,'Player Stats'!E:E) -> 1.4756098 | J3: =_xlfn.XLOOKUP(C3,'Player Stats'!A:A,'Player Stats'!F:F) -> 0.5 | K3: =_xlfn.XLOOKUP(C3,'Player Stats'!A:A,'Player Stats'!G:G) -> 1.8658537 | L3: =_xlfn.XLOOKUP(C3,'Player Stats'!A:A,'Player Stats'!H:H) -> 20.96748 | M3: =F3*G3 -> 783 | N3: =F3*H3 -> 324 | O3: =F3*I3 -> 121 | P3: =F3*J3 -> 41 | Q3: =F3*K3 -> 153 | R3: =F3*L3 -> 1719.3333 | S3: =(M3/D3)*1000000 -> 333.25133 | T3: =(N3/D3)*1000000 -> 137.8971 | U3: =(O3/D3)*1000000 -> 51.49861 | V3: =(P3/D3)*1000000 -> 17.449942 | W3: =(Q3/D3)*1000000 -> 65.118077 | X3: =IF(AND(F3>=20,L3>=15),"Yes","No") -> Yes
A4: 2025-26 | B4: 950065 | C4: Tony Bradley | D4: 123945 | E4: Atlanta Hawks | F4: =_xlfn.XLOOKUP(C4,'Player Stats'!A:A,'Player Stats'!B:B) -> 45 | G4: =_xlfn.XLOOKUP(C4,'Player Stats'!A:A,'Player Stats'!C:C) -> 3.8444444 | H4: =_xlfn.XLOOKUP(C4,'Player Stats'!A:A,'Player Stats'!D:D) -> 2.8222222 | I4: =_xlfn.XLOOKUP(C4,'Player Stats'!A:A,'Player Stats'!E:E) -> 0.55555556 | J4: =_xlfn.XLOOKUP(C4,'Player Stats'!A:A,'Player Stats'!F:F) -> 0.17777778 | K4: =_xlfn.XLOOKUP(C4,'Player Stats'!A:A,'Player Stats'!G:G) -> 0.22222222 | L4: =_xlfn.XLOOKUP(C4,'Player Stats'!A:A,'Player Stats'!H:H) -> 10.916667 | M4: =F4*G4 -> 173 | N4: =F4*H4 -> 127 | O4: =F4*I4 -> 25 | P4: =F4*J4 -> 8 | Q4: =F4*K4 -> 10 | R4: =F4*L4 -> 491.25 | S4: =(M4/D4)*1000000 -> 1395.7804 | T4: =(N4/D4)*1000000 -> 1024.648 | U4: =(O4/D4)*1000000 -> 201.70237 | V4: =(P4/D4)*1000000 -> 64.544758 | W4: =(Q4/D4)*1000000 -> 80.680947 | X4: =IF(AND(F4>=20,L4>=15),"Yes","No") -> No
A5: 2025-26 | B5: 1251665 | C5: Dylan Cardwell | D5: 1218461 | E5: Sacramento Kings | F5: =_xlfn.XLOOKUP(C5,'Player Stats'!A:A,'Player Stats'!B:B) -> 44 | G5: =_xlfn.XLOOKUP(C5,'Player Stats'!A:A,'Player Stats'!C:C) -> 5.4090909 | H5: =_xlfn.XLOOKUP(C5,'Player Stats'!A:A,'Player Stats'!D:D) -> 7.5454545 | I5: =_xlfn.XLOOKUP(C5,'Player Stats'!A:A,'Player Stats'!E:E) -> 1.4090909 | J5: =_xlfn.XLOOKUP(C5,'Player Stats'!A:A,'Player Stats'!F:F) -> 0.68181818 | K5: =_xlfn.XLOOKUP(C5,'Player Stats'!A:A,'Player Stats'!G:G) -> 1.5227273 | L5: =_xlfn.XLOOKUP(C5,'Player Stats'!A:A,'Player Stats'!H:H) -> 20.602273 | M5: =F5*G5 -> 238 | N5: =F5*H5 -> 332 | O5: =F5*I5 -> 62 | P5: =F5*J5 -> 30 | Q5: =F5*K5 -> 67 | R5: =F5*L5 -> 906.5 | S5: =(M5/D5)*1000000 -> 195.32837 | T5: =(N5/D5)*1000000 -> 272.47487 | U5: =(O5/D5)*1000000 -> 50.883861 | V5: =(P5/D5)*1000000 -> 24.621223 | W5: =(Q5/D5)*1000000 -> 54.987398 | X5: =IF(AND(F5>=20,L5>=15),"Yes","No") -> Yes
A6: 2025-26 | B6: 1194704 | C6: RayJ Dennis | D6: 67267 | E6: Los Angeles Clippers | F6: =_xlfn.XLOOKUP(C6,'Player Stats'!A:A,'Player Stats'!B:B) -> 17 | G6: =_xlfn.XLOOKUP(C6,'Player Stats'!A:A,'Player Stats'!C:C) -> 4.3529412 | H6: =_xlfn.XLOOKUP(C6,'Player Stats'!A:A,'Player Stats'!D:D) -> 1.5294118 | I6: =_xlfn.XLOOKUP(C6,'Player Stats'!A:A,'Player Stats'!E:E) -> 1.9411765 | J6: =_xlfn.XLOOKUP(C6,'Player Stats'!A:A,'Player Stats'!F:F) -> 0.23529412 | K6: =_xlfn.XLOOKUP(C6,'Player Stats'!A:A,'Player Stats'!G:G) -> 0.23529412 | L6: =_xlfn.XLOOKUP(C6,'Player Stats'!A:A,'Player Stats'!H:H) -> 12.130392 | M6: =F6*G6 -> 74 | N6: =F6*H6 -> 26 | O6: =F6*I6 -> 33 | P6: =F6*J6 -> 4 | Q6: =F6*K6 -> 4 | R6: =F6*L6 -> 206.21667 | S6: =(M6/D6)*1000000 -> 1100.0937 | T6: =(N6/D6)*1000000 -> 386.51939 | U6: =(O6/D6)*1000000 -> 490.58231 | V6: =(P6/D6)*1000000 -> 59.464522 | W6: =(Q6/D6)*1000000 -> 59.464522 | X6: =IF(AND(F6>=20,L6>=15),"Yes","No") -> No
A7: 2025-26 | B7: 1324442 | C7: Julian Reese | D7: 141554 | E7: Washington Wizards | F7: =_xlfn.XLOOKUP(C7,'Player Stats'!A:A,'Player Stats'!B:B) -> 13 | G7: =_xlfn.XLOOKUP(C7,'Player Stats'!A:A,'Player Stats'!C:C) -> 11.846154 | H7: =_xlfn.XLOOKUP(C7,'Player Stats'!A:A,'Player Stats'!D:D) -> 10.538462 | I7: =_xlfn.XLOOKUP(C7,'Player Stats'!A:A,'Player Stats'!E:E) -> 1.8461538 | J7: =_xlfn.XLOOKUP(C7,'Player Stats'!A:A,'Player Stats'!F:F) -> 1.3846154 | K7: =_xlfn.XLOOKUP(C7,'Player Stats'!A:A,'Player Stats'!G:G) -> 0.61538462 | L7: =_xlfn.XLOOKUP(C7,'Player Stats'!A:A,'Player Stats'!H:H) -> 30.884615 | M7: =F7*G7 -> 154 | N7: =F7*H7 -> 137 | O7: =F7*I7 -> 24 | P7: =F7*J7 -> 18 | Q7: =F7*K7 -> 8 | R7: =F7*L7 -> 401.5 | S7: =(M7/D7)*1000000 -> 1087.924 | T7: =(N7/D7)*1000000 -> 967.82853 | U7: =(O7/D7)*1000000 -> 169.5466 | V7: =(P7/D7)*1000000 -> 127.15995 | W7: =(Q7/D7)*1000000 -> 56.515535 | X7: =IF(AND(F7>=20,L7>=15),"Yes","No") -> No
A8: 2025-26 | B8: 1134766 | C8: Cormac Ryan | D8: 147988 | E8: Milwaukee Bucks | F8: =_xlfn.XLOOKUP(C8,'Player Stats'!A:A,'Player Stats'!B:B) -> 11 | G8: =_xlfn.XLOOKUP(C8,'Player Stats'!A:A,'Player Stats'!C:C) -> 14.272727 | H8: =_xlfn.XLOOKUP(C8,'Player Stats'!A:A,'Player Stats'!D:D) -> 2.5454545 | I8: =_xlfn.XLOOKUP(C8,'Player Stats'!A:A,'Player Stats'!E:E) -> 1.7272727 | J8: =_xlfn.XLOOKUP(C8,'Player Stats'!A:A,'Player Stats'!F:F) -> 1 | K8: =_xlfn.XLOOKUP(C8,'Player Stats'!A:A,'Player Stats'!G:G) -> 0.27272727 | L8: =_xlfn.XLOOKUP(C8,'Player Stats'!A:A,'Player Stats'!H:H) -> 24.607576 | M8: =F8*G8 -> 157 | N8: =F8*H8 -> 28 | O8: =F8*I8 -> 19 | P8: =F8*J8 -> 11 | Q8: =F8*K8 -> 3 | R8: =F8*L8 -> 270.68333 | S8: =(M8/D8)*1000000 -> 1060.8968 | T8: =(N8/D8)*1000000 -> 189.20453 | U8: =(O8/D8)*1000000 -> 128.38879 | V8: =(P8/D8)*1000000 -> 74.330351 | W8: =(Q8/D8)*1000000 -> 20.271914 | X8: =IF(AND(F8>=20,L8>=15),"Yes","No") -> No
A9: 2025-26 | C9: Tyler Burton | D9: 146306 | E9: Memphis Grizzlies | F9: =_xlfn.XLOOKUP(C9,'Player Stats'!A:A,'Player Stats'!B:B) -> 12 | G9: =_xlfn.XLOOKUP(C9,'Player Stats'!A:A,'Player Stats'!C:C) -> 10.75 | H9: =_xlfn.XLOOKUP(C9,'Player Stats'!A:A,'Player Stats'!D:D) -> 4.1666667 | I9: =_xlfn.XLOOKUP(C9,'Player Stats'!A:A,'Player Stats'!E:E) -> 1 | J9: =_xlfn.XLOOKUP(C9,'Player Stats'!A:A,'Player Stats'!F:F) -> 0.91666667 | K9: =_xlfn.XLOOKUP(C9,'Player Stats'!A:A,'Player Stats'!G:G) -> 0.33333333 | L9: =_xlfn.XLOOKUP(C9,'Player Stats'!A:A,'Player Stats'!H:H) -> 25.5625 | M9: =F9*G9 -> 129 | N9: =F9*H9 -> 50 | O9: =F9*I9 -> 12 | P9: =F9*J9 -> 11 | Q9: =F9*K9 -> 4 | R9: =F9*L9 -> 306.75 | S9: =(M9/D9)*1000000 -> 881.71367 | T9: =(N9/D9)*1000000 -> 341.74948 | U9: =(O9/D9)*1000000 -> 82.019876 | V9: =(P9/D9)*1000000 -> 75.184886 | W9: =(Q9/D9)*1000000 -> 27.339959 | X9: =IF(AND(F9>=20,L9>=15),"Yes","No") -> No
A10: 2025-26 | B10: 1134179 | C10: Blake Hinson | D10: 202680 | E10: Utah Jazz | F10: =_xlfn.XLOOKUP(C10,'Player Stats'!A:A,'Player Stats'!B:B) -> 14 | G10: =_xlfn.XLOOKUP(C10,'Player Stats'!A:A,'Player Stats'!C:C) -> 11.928571 | H10: =_xlfn.XLOOKUP(C10,'Player Stats'!A:A,'Player Stats'!D:D) -> 2.3571429 | I10: =_xlfn.XLOOKUP(C10,'Player Stats'!A:A,'Player Stats'!E:E) -> 1.1428571 | J10: =_xlfn.XLOOKUP(C10,'Player Stats'!A:A,'Player Stats'!F:F) -> 0.35714286 | K10: =_xlfn.XLOOKUP(C10,'Player Stats'!A:A,'Player Stats'!G:G) -> 0.14285714 | L10: =_xlfn.XLOOKUP(C10,'Player Stats'!A:A,'Player Stats'!H:H) -> 20.388095 | M10: =F10*G10 -> 167 | N10: =F10*H10 -> 33 | O10: =F10*I10 -> 16 | P10: =F10*J10 -> 5 | Q10: =F10*K10 -> 2 | R10: =F10*L10 -> 285.43333 | S10: =(M10/D10)*1000000 -> 823.95895 | T10: =(N10/D10)*1000000 -> 162.81824 | U10: =(O10/D10)*1000000 -> 78.942175 | V10: =(P10/D10)*1000000 -> 24.66943 | W10: =(Q10/D10)*1000000 -> 9.8677719 | X10: =IF(AND(F10>=20,L10>=15),"Yes","No") -> No
A11: 2025-26 | B11: 1232503 | C11: Toby Okani | D11: 73153 | E11: Memphis Grizzlies | F11: =_xlfn.XLOOKUP(C11,'Player Stats'!A:A,'Player Stats'!B:B) -> 6 | G11: =_xlfn.XLOOKUP(C11,'Player Stats'!A:A,'Player Stats'!C:C) -> 10 | H11: =_xlfn.XLOOKUP(C11,'Player Stats'!A:A,'Player Stats'!D:D) -> 3.5 | I11: =_xlfn.XLOOKUP(C11,'Player Stats'!A:A,'Player Stats'!E:E) -> 1 | J11: =_xlfn.XLOOKUP(C11,'Player Stats'!A:A,'Player Stats'!F:F) -> 0.66666667 | K11: =_xlfn.XLOOKUP(C11,'Player Stats'!A:A,'Player Stats'!G:G) -> 0.5 | L11: =_xlfn.XLOOKUP(C11,'Player Stats'!A:A,'Player Stats'!H:H) -> 36.180556 | M11: =F11*G11 -> 60 | N11: =F11*H11 -> 21 | O11: =F11*I11 -> 6 | P11: =F11*J11 -> 4 | Q11: =F11*K11 -> 3 | R11: =F11*L11 -> 217.08333 | S11: =(M11/D11)*1000000 -> 820.19876 | T11: =(N11/D11)*1000000 -> 287.06957 | U11: =(O11/D11)*1000000 -> 82.019876 | V11: =(P11/D11)*1000000 -> 54.679917 | W11: =(Q11/D11)*1000000 -> 41.009938 | X11: =IF(AND(F11>=20,L11>=15),"Yes","No") -> No
A12: 2025-26 | B12: 1343052 | C12: John Poulakidas | D12: 141554 | E12: Dallas Mavericks | F12: =_xlfn.XLOOKUP(C12,'Player Stats'!A:A,'Player Stats'!B:B) -> 13 | G12: =_xlfn.XLOOKUP(C12,'Player Stats'!A:A,'Player Stats'!C:C) -> 8.8461538 | H12: =_xlfn.XLOOKUP(C12,'Player Stats'!A:A,'Player Stats'!D:D) -> 2.3076923 | I12: =_xlfn.XLOOKUP(C12,'Player Stats'!A:A,'Player Stats'!E:E) -> 0.84615385 | J12: =_xlfn.XLOOKUP(C12,'Player Stats'!A:A,'Player Stats'!F:F) -> 0.53846154 | K12: =_xlfn.XLOOKUP(C12,'Player Stats'!A:A,'Player Stats'!G:G) -> 0.30769231 | L12: =_xlfn.XLOOKUP(C12,'Player Stats'!A:A,'Player Stats'!H:H) -> 19.494872 | M12: =F12*G12 -> 115 | N12: =F12*H12 -> 30 | O12: =F12*I12 -> 11 | P12: =F12*J12 -> 7 | Q12: =F12*K12 -> 4 | R12: =F12*L12 -> 253.43333 | S12: =(M12/D12)*1000000 -> 812.41081 | T12: =(N12/D12)*1000000 -> 211.93326 | U12: =(O12/D12)*1000000 -> 77.70886 | V12: =(P12/D12)*1000000 -> 49.451093 | W12: =(Q12/D12)*1000000 -> 28.257767 | X12: =IF(AND(F12>=20,L12>=15),"Yes","No") -> No
A13: 2025-26 | B13: 1236052 | C13: Ryan Kalkbrenner | D13: 2296274 | E13: Charlotte Hornets | F13: =_xlfn.XLOOKUP(C13,'Player Stats'!A:A,'Player Stats'!B:B) -> 71 | G13: =_xlfn.XLOOKUP(C13,'Player Stats'!A:A,'Player Stats'!C:C) -> 7.4507042 | H13: =_xlfn.XLOOKUP(C13,'Player Stats'!A:A,'Player Stats'!D:D) -> 5.4225352 | I13: =_xlfn.XLOOKUP(C13,'Player Stats'!A:A,'Player Stats'!E:E) -> 0.78873239 | J13: =_xlfn.XLOOKUP(C13,'Player Stats'!A:A,'Player Stats'!F:F) -> 0.47887324 | K13: =_xlfn.XLOOKUP(C13,'Player Stats'!A:A,'Player Stats'!G:G) -> 1.4366197 | L13: =_xlfn.XLOOKUP(C13,'Player Stats'!A:A,'Player Stats'!H:H) -> 21.262676 | M13: =F13*G13 -> 529 | N13: =F13*H13 -> 385 | O13: =F13*I13 -> 56 | P13: =F13*J13 -> 34 | Q13: =F13*K13 -> 102 | R13: =F13*L13 -> 1509.65 | S13: =(M13/D13)*1000000 -> 230.3732 | T13: =(N13/D13)*1000000 -> 167.66292 | U13: =(O13/D13)*1000000 -> 24.387334 | V13: =(P13/D13)*1000000 -> 14.806595 | W13: =(Q13/D13)*1000000 -> 44.419786 | X13: =IF(AND(F13>=20,L13>=15),"Yes","No") -> Yes
A14: 2025-26 | C14: Lucas Williamson | D14: 95099 | E14: Memphis Grizzlies | F14: =_xlfn.XLOOKUP(C14,'Player Stats'!A:A,'Player Stats'!B:B) -> 7 | G14: =_xlfn.XLOOKUP(C14,'Player Stats'!A:A,'Player Stats'!C:C) -> 10.428571 | H14: =_xlfn.XLOOKUP(C14,'Player Stats'!A:A,'Player Stats'!D:D) -> 5.4285714 | I14: =_xlfn.XLOOKUP(C14,'Player Stats'!A:A,'Player Stats'!E:E) -> 2.5714286 | J14: =_xlfn.XLOOKUP(C14,'Player Stats'!A:A,'Player Stats'!F:F) -> 1.5714286 | K14: =_xlfn.XLOOKUP(C14,'Player Stats'!A:A,'Player Stats'!G:G) -> 0.14285714 | L14: =_xlfn.XLOOKUP(C14,'Player Stats'!A:A,'Player Stats'!H:H) -> 31.961905 | M14: =F14*G14 -> 73 | N14: =F14*H14 -> 38 | O14: =F14*I14 -> 18 | P14: =F14*J14 -> 11 | Q14: =F14*K14 -> 1 | R14: =F14*L14 -> 223.73333 | S14: =(M14/D14)*1000000 -> 767.62111 | T14: =(N14/D14)*1000000 -> 399.58359 | U14: =(O14/D14)*1000000 -> 189.27644 | V14: =(P14/D14)*1000000 -> 115.66893 | W14: =(Q14/D14)*1000000 -> 10.515358 | X14: =IF(AND(F14>=20,L14>=15),"Yes","No") -> No
A15: 2025-26 | B15: 1401778 | C15: Dariq Whitehead | D15: 131970 | E15: Memphis Grizzlies | F15: =_xlfn.XLOOKUP(C15,'Player Stats'!A:A,'Player Stats'!B:B) -> 6 | G15: =_xlfn.XLOOKUP(C15,'Player Stats'!A:A,'Player Stats'!C:C) -> 16.333333 | H15: =_xlfn.XLOOKUP(C15,'Player Stats'!A:A,'Player Stats'!D:D) -> 4 | I15: =_xlfn.XLOOKUP(C15,'Player Stats'!A:A,'Player Stats'!E:E) -> 1.5 | J15: =_xlfn.XLOOKUP(C15,'Player Stats'!A:A,'Player Stats'!F:F) -> 0.66666667 | K15: =_xlfn.XLOOKUP(C15,'Player Stats'!A:A,'Player Stats'!G:G) -> 0 | L15: =_xlfn.XLOOKUP(C15,'Player Stats'!A:A,'Player Stats'!H:H) -> 30.469444 | M15: =F15*G15 -> 98 | N15: =F15*H15 -> 24 | O15: =F15*I15 -> 9 | P15: =F15*J15 -> 4 | Q15: =F15*K15 -> 0 | R15: =F15*L15 -> 182.81667 | S15: =(M15/D15)*1000000 -> 742.59301 | T15: =(N15/D15)*1000000 -> 181.85951 | U15: =(O15/D15)*1000000 -> 68.197318 | V15: =(P15/D15)*1000000 -> 30.309919 | W15: =(Q15/D15)*1000000 -> 0 | X15: =IF(AND(F15>=20,L15>=15),"Yes","No") -> No
A16: 2025-26 | B16: 1176586 | C16: Spencer Jones | D16: 1016457 | E16: Denver Nuggets | F16: =_xlfn.XLOOKUP(C16,'Player Stats'!A:A,'Player Stats'!B:B) -> 70 | G16: =_xlfn.XLOOKUP(C16,'Player Stats'!A:A,'Player Stats'!C:C) -> 5.5857143 | H16: =_xlfn.XLOOKUP(C16,'Player Stats'!A:A,'Player Stats'!D:D) -> 3.1571429 | I16: =_xlfn.XLOOKUP(C16,'Player Stats'!A:A,'Player Stats'!E:E) -> 0.75714286 | J16: =_xlfn.XLOOKUP(C16,'Player Stats'!A:A,'Player Stats'!F:F) -> 0.8 | K16: =_xlfn.XLOOKUP(C16,'Player Stats'!A:A,'Player Stats'!G:G) -> 0.51428571 | L16: =_xlfn.XLOOKUP(C16,'Player Stats'!A:A,'Player Stats'!H:H) -> 22.315952 | M16: =F16*G16 -> 391 | N16: =F16*H16 -> 221 | O16: =F16*I16 -> 53 | P16: =F16*J16 -> 56 | Q16: =F16*K16 -> 36 | R16: =F16*L16 -> 1562.1167 | S16: =(M16/D16)*1000000 -> 384.66949 | T16: =(N16/D16)*1000000 -> 217.42189 | U16: =(O16/D16)*1000000 -> 52.141901 | V16: =(P16/D16)*1000000 -> 55.093329 | W16: =(Q16/D16)*1000000 -> 35.41714 | X16: =IF(AND(F16>=20,L16>=15),"Yes","No") -> Yes
A17: 2025-26 | B17: 1134107 | C17: Tyrese Martin | D17: 170508 | E17: Philadelphia 76ers | F17: =_xlfn.XLOOKUP(C17,'Player Stats'!A:A,'Player Stats'!B:B) -> 46 | G17: =_xlfn.XLOOKUP(C17,'Player Stats'!A:A,'Player Stats'!C:C) -> 6.3043478 | H17: =_xlfn.XLOOKUP(C17,'Player Stats'!A:A,'Player Stats'!D:D) -> 2.5217391 | I17: =_xlfn.XLOOKUP(C17,'Player Stats'!A:A,'Player Stats'!E:E) -> 1.6956522 | J17: =_xlfn.XLOOKUP(C17,'Player Stats'!A:A,'Player Stats'!F:F) -> 0.54347826 | K17: =_xlfn.XLOOKUP(C17,'Player Stats'!A:A,'Player Stats'!G:G) -> 0.13043478 | L17: =_xlfn.XLOOKUP(C17,'Player Stats'!A:A,'Player Stats'!H:H) -> 16.882609 | M17: =F17*G17 -> 290 | N17: =F17*H17 -> 116 | O17: =F17*I17 -> 78 | P17: =F17*J17 -> 25 | Q17: =F17*K17 -> 6 | R17: =F17*L17 -> 776.6 | S17: =(M17/D17)*1000000 -> 1700.8 | T17: =(N17/D17)*1000000 -> 680.31998 | U17: =(O17/D17)*1000000 -> 457.45654 | V17: =(P17/D17)*1000000 -> 146.62069 | W17: =(Q17/D17)*1000000 -> 35.188965 | X17: =IF(AND(F17>=20,L17>=15),"Yes","No") -> Yes
A18: 2025-26 | B18: 1328253 | C18: Kennedy Chandler | D18: 235460 | E18: Utah Jazz | F18: =_xlfn.XLOOKUP(C18,'Player Stats'!A:A,'Player Stats'!B:B) -> 11 | G18: =_xlfn.XLOOKUP(C18,'Player Stats'!A:A,'Player Stats'!C:C) -> 15 | H18: =_xlfn.XLOOKUP(C18,'Player Stats'!A:A,'Player Stats'!D:D) -> 3.3636364 | I18: =_xlfn.XLOOKUP(C18,'Player Stats'!A:A,'Player Stats'!E:E) -> 6.7272727 | J18: =_xlfn.XLOOKUP(C18,'Player Stats'!A:A,'Player Stats'!F:F) -> 1 | K18: =_xlfn.XLOOKUP(C18,'Player Stats'!A:A,'Player Stats'!G:G) -> 0.18181818 | L18: =_xlfn.XLOOKUP(C18,'Player Stats'!A:A,'Player Stats'!H:H) -> 32.293939 | M18: =F18*G18 -> 165 | N18: =F18*H18 -> 37 | O18: =F18*I18 -> 74 | P18: =F18*J18 -> 11 | Q18: =F18*K18 -> 2 | R18: =F18*L18 -> 355.23333 | S18: =(M18/D18)*1000000 -> 700.75597 | T18: =(N18/D18)*1000000 -> 157.13922 | U18: =(O18/D18)*1000000 -> 314.27843 | V18: =(P18/D18)*1000000 -> 46.717064 | W18: =(Q18/D18)*1000000 -> 8.4940117 | X18: =IF(AND(F18>=20,L18>=15),"Yes","No") -> No
A19: 2025-26 | B19: 1135981 | C19: Jalen Slawson | D19: 141554 | E19: Indiana Pacers | F19: =_xlfn.XLOOKUP(C19,'Player Stats'!A:A,'Player Stats'!B:B) -> 13 | G19: =_xlfn.XLOOKUP(C19,'Player Stats'!A:A,'Player Stats'!C:C) -> 7.3076923 | H19: =_xlfn.XLOOKUP(C19,'Player Stats'!A:A,'Player Stats'!D:D) -> 4.3846154 | I19: =_xlfn.XLOOKUP(C19,'Player Stats'!A:A,'Player Stats'!E:E) -> 2.7692308 | J19: =_xlfn.XLOOKUP(C19,'Player Stats'!A:A,'Player Stats'!F:F) -> 1.5384615 | K19: =_xlfn.XLOOKUP(C19,'Player Stats'!A:A,'Player Stats'!G:G) -> 1.0769231 | L19: =_xlfn.XLOOKUP(C19,'Player Stats'!A:A,'Player Stats'!H:H) -> 23.887179 | M19: =F19*G19 -> 95 | N19: =F19*H19 -> 57 | O19: =F19*I19 -> 36 | P19: =F19*J19 -> 20 | Q19: =F19*K19 -> 14 | R19: =F19*L19 -> 310.53333 | S19: =(M19/D19)*1000000 -> 671.12197 | T19: =(N19/D19)*1000000 -> 402.67318 | U19: =(O19/D19)*1000000 -> 254.31991 | V19: =(P19/D19)*1000000 -> 141.28884 | W19: =(Q19/D19)*1000000 -> 98.902186 | X19: =IF(AND(F19>=20,L19>=15),"Yes","No") -> No
A20: 2025-26 | B20: 1138380 | C20: Leaky Black | D20: 164074 | E20: Washington Wizards | F20: =_xlfn.XLOOKUP(C20,'Player Stats'!A:A,'Player Stats'!B:B) -> 15 | G20: =_xlfn.XLOOKUP(C20,'Player Stats'!A:A,'Player Stats'!C:C) -> 7.0666667 | H20: =_xlfn.XLOOKUP(C20,'Player Stats'!A:A,'Player Stats'!D:D) -> 5 | I20: =_xlfn.XLOOKUP(C20,'Player Stats'!A:A,'Player Stats'!E:E) -> 1.4666667 | J20: =_xlfn.XLOOKUP(C20,'Player Stats'!A:A,'Player Stats'!F:F) -> 1.2 | K20: =_xlfn.XLOOKUP(C20,'Player Stats'!A:A,'Player Stats'!G:G) -> 0.53333333 | L20: =_xlfn.XLOOKUP(C20,'Player Stats'!A:A,'Player Stats'!H:H) -> 28.872222 | M20: =F20*G20 -> 106 | N20: =F20*H20 -> 75 | O20: =F20*I20 -> 22 | P20: =F20*J20 -> 18 | Q20: =F20*K20 -> 8 | R20: =F20*L20 -> 433.08333 | S20: =(M20/D20)*1000000 -> 646.04995 | T20: =(N20/D20)*1000000 -> 457.11082 | U20: =(O20/D20)*1000000 -> 134.08584 | V20: =(P20/D20)*1000000 -> 109.7066 | W20: =(Q20/D20)*1000000 -> 48.758487 | X20: =IF(AND(F20>=20,L20>=15),"Yes","No") -> No
A21: 2025-26 | B21: 1239611 | C21: Dalen Terry | D21: 298486 | E21: Philadelphia 76ers | F21: =_xlfn.XLOOKUP(C21,'Player Stats'!A:A,'Player Stats'!B:B) -> 55 | G21: =_xlfn.XLOOKUP(C21,'Player Stats'!A:A,'Player Stats'!C:C) -> 3.4363636 | H21: =_xlfn.XLOOKUP(C21,'Player Stats'!A:A,'Player Stats'!D:D) -> 1.6363636 | I21: =_xlfn.XLOOKUP(C21,'Player Stats'!A:A,'Player Stats'!E:E) -> 1.3272727 | J21: =_xlfn.XLOOKUP(C21,'Player Stats'!A:A,'Player Stats'!F:F) -> 0.61818182 | K21: =_xlfn.XLOOKUP(C21,'Player Stats'!A:A,'Player Stats'!G:G) -> 0.27272727 | L21: =_xlfn.XLOOKUP(C21,'Player Stats'!A:A,'Player Stats'!H:H) -> 10.736364 | M21: =F21*G21 -> 189 | N21: =F21*H21 -> 90 | O21: =F21*I21 -> 73 | P21: =F21*J21 -> 34 | Q21: =F21*K21 -> 15 | R21: =F21*L21 -> 590.5 | S21: =(M21/D21)*1000000 -> 633.19553 | T21: =(N21/D21)*1000000 -> 301.52168 | U21: =(O21/D21)*1000000 -> 244.56758 | V21: =(P21/D21)*1000000 -> 113.90819 | W21: =(Q21/D21)*1000000 -> 50.253613 | X21: =IF(AND(F21>=20,L21>=15),"Yes","No") -> No
A22: 2025-26 | B22: 1193674 | C22: Christian Koloko | D22: 115817 | E22: Los Angeles Lakers | F22: =_xlfn.XLOOKUP(C22,'Player Stats'!A:A,'Player Stats'!B:B) -> 27 | G22: =_xlfn.XLOOKUP(C22,'Player Stats'!A:A,'Player Stats'!C:C) -> 2.7037037 | H22: =_xlfn.XLOOKUP(C22,'Player Stats'!A:A,'Player Stats'!D:D) -> 3 | I22: =_xlfn.XLOOKUP(C22,'Player Stats'!A:A,'Player Stats'!E:E) -> 0.66666667 | J22: =_xlfn.XLOOKUP(C22,'Player Stats'!A:A,'Player Stats'!F:F) -> 0.51851852 | K22: =_xlfn.XLOOKUP(C22,'Player Stats'!A:A,'Player Stats'!G:G) -> 0.85185185 | L22: =_xlfn.XLOOKUP(C22,'Player Stats'!A:A,'Player Stats'!H:H) -> 13.210494 | M22: =F22*G22 -> 73 | N22: =F22*H22 -> 81 | O22: =F22*I22 -> 18 | P22: =F22*J22 -> 14 | Q22: =F22*K22 -> 23 | R22: =F22*L22 -> 356.68333 | S22: =(M22/D22)*1000000 -> 630.3047 | T22: =(N22/D22)*1000000 -> 699.37919 | U22: =(O22/D22)*1000000 -> 155.4176 | V22: =(P22/D22)*1000000 -> 120.88035 | W22: =(Q22/D22)*1000000 -> 198.58915 | X22: =IF(AND(F22>=20,L22>=15),"Yes","No") -> No
A23: 2025-26 | B23: 1433295 | C23: Rayan Rupert | D23: 260656 | E23: Memphis Grizzlies | F23: =_xlfn.XLOOKUP(C23,'Player Stats'!A:A,'Player Stats'!B:B) -> 64 | G23: =_xlfn.XLOOKUP(C23,'Player Stats'!A:A,'Player Stats'!C:C) -> 5.1875 | H23: =_xlfn.XLOOKUP(C23,'Player Stats'!A:A,'Player Stats'!D:D) -> 2.9375 | I23: =_xlfn.XLOOKUP(C23,'Player Stats'!A:A,'Player Stats'!E:E) -> 1.0625 | J23: =_xlfn.XLOOKUP(C23,'Player Stats'!A:A,'Player Stats'!F:F) -> 0.859375 | K23: =_xlfn.XLOOKUP(C23,'Player Stats'!A:A,'Player Stats'!G:G) -> 0.140625 | L23: =_xlfn.XLOOKUP(C23,'Player Stats'!A:A,'Player Stats'!H:H) -> 16.759375 | M23: =F23*G23 -> 332 | N23: =F23*H23 -> 188 | O23: =F23*I23 -> 68 | P23: =F23*J23 -> 55 | Q23: =F23*K23 -> 9 | R23: =F23*L23 -> 1072.6 | S23: =(M23/D23)*1000000 -> 1273.7094 | T23: =(N23/D23)*1000000 -> 721.25714 | U23: =(O23/D23)*1000000 -> 260.88024 | V23: =(P23/D23)*1000000 -> 211.00608 | W23: =(Q23/D23)*1000000 -> 34.528267 | X23: =IF(AND(F23>=20,L23>=15),"Yes","No") -> Yes
A24: 2025-26 | B24: 1232477 | C24: Oso Ighodaro | D24: 1955377 | E24: Phoenix Suns | F24: =_xlfn.XLOOKUP(C24,'Player Stats'!A:A,'Player Stats'!B:B) -> 88 | G24: =_xlfn.XLOOKUP(C24,'Player Stats'!A:A,'Player Stats'!C:C) -> 6.5227273 | H24: =_xlfn.XLOOKUP(C24,'Player Stats'!A:A,'Player Stats'!D:D) -> 5.1477273 | I24: =_xlfn.XLOOKUP(C24,'Player Stats'!A:A,'Player Stats'!E:E) -> 2.3636364 | J24: =_xlfn.XLOOKUP(C24,'Player Stats'!A:A,'Player Stats'!F:F) -> 0.875 | K24: =_xlfn.XLOOKUP(C24,'Player Stats'!A:A,'Player Stats'!G:G) -> 0.69318182 | L24: =_xlfn.XLOOKUP(C24,'Player Stats'!A:A,'Player Stats'!H:H) -> 22.575947 | M24: =F24*G24 -> 574 | N24: =F24*H24 -> 453 | O24: =F24*I24 -> 208 | P24: =F24*J24 -> 77 | Q24: =F24*K24 -> 61 | R24: =F24*L24 -> 1986.6833 | S24: =(M24/D24)*1000000 -> 293.54953 | T24: =(N24/D24)*1000000 -> 231.66888 | U24: =(O24/D24)*1000000 -> 106.37335 | V24: =(P24/D24)*1000000 -> 39.378596 | W24: =(Q24/D24)*1000000 -> 31.19603 | X24: =IF(AND(F24>=20,L24>=15),"Yes","No") -> Yes
A25: 2025-26 | B25: 1326453 | C25: Maxime Raynaud | D25: 1272870 | E25: Sacramento Kings | F25: =_xlfn.XLOOKUP(C25,'Player Stats'!A:A,'Player Stats'!B:B) -> 74 | G25: =_xlfn.XLOOKUP(C25,'Player Stats'!A:A,'Player Stats'!C:C) -> 12.459459 | H25: =_xlfn.XLOOKUP(C25,'Player Stats'!A:A,'Player Stats'!D:D) -> 7.5135135 | I25: =_xlfn.XLOOKUP(C25,'Player Stats'!A:A,'Player Stats'!E:E) -> 1.3513514 | J25: =_xlfn.XLOOKUP(C25,'Player Stats'!A:A,'Player Stats'!F:F) -> 0.51351351 | K25: =_xlfn.XLOOKUP(C25,'Player Stats'!A:A,'Player Stats'!G:G) -> 0.52702703 | L25: =_xlfn.XLOOKUP(C25,'Player Stats'!A:A,'Player Stats'!H:H) -> 26.538964 | M25: =F25*G25 -> 922 | N25: =F25*H25 -> 556 | O25: =F25*I25 -> 100 | P25: =F25*J25 -> 38 | Q25: =F25*K25 -> 39 | R25: =F25*L25 -> 1963.8833 | S25: =(M25/D25)*1000000 -> 724.34734 | T25: =(N25/D25)*1000000 -> 436.80816 | U25: =(O25/D25)*1000000 -> 78.562618 | V25: =(P25/D25)*1000000 -> 29.853795 | W25: =(Q25/D25)*1000000 -> 30.639421 | X25: =IF(AND(F25>=20,L25>=15),"Yes","No") -> Yes
A26: 2025-26 | B26: 1429357 | C26: Tyler Smith | D26: 93589 | E26: Houston Rockets | F26: =_xlfn.XLOOKUP(C26,'Player Stats'!A:A,'Player Stats'!B:B) -> 12 | G26: =_xlfn.XLOOKUP(C26,'Player Stats'!A:A,'Player Stats'!C:C) -> 4.6666667 | H26: =_xlfn.XLOOKUP(C26,'Player Stats'!A:A,'Player Stats'!D:D) -> 2.75 | I26: =_xlfn.XLOOKUP(C26,'Player Stats'!A:A,'Player Stats'!E:E) -> 0.41666667 | J26: =_xlfn.XLOOKUP(C26,'Player Stats'!A:A,'Player Stats'!F:F) -> 0.5 | K26: =_xlfn.XLOOKUP(C26,'Player Stats'!A:A,'Player Stats'!G:G) -> 0 | L26: =_xlfn.XLOOKUP(C26,'Player Stats'!A:A,'Player Stats'!H:H) -> 13.798611 | M26: =F26*G26 -> 56 | N26: =F26*H26 -> 33 | O26: =F26*I26 -> 5 | P26: =F26*J26 -> 6 | Q26: =F26*K26 -> 0 | R26: =F26*L26 -> 165.58333 | S26: =(M26/D26)*1000000 -> 598.36092 | T26: =(N26/D26)*1000000 -> 352.60554 | U26: =(O26/D26)*1000000 -> 53.425082 | V26: =(P26/D26)*1000000 -> 64.110098 | W26: =(Q26/D26)*1000000 -> 0 | X26: =IF(AND(F26>=20,L26>=15),"Yes","No") -> No
A27: 2025-26 | C27: Malachi Smith | D27: 212144 | E27: Brooklyn Nets | F27: =_xlfn.XLOOKUP(C27,'Player Stats'!A:A,'Player Stats'!B:B) -> 15 | G27: =_xlfn.XLOOKUP(C27,'Player Stats'!A:A,'Player Stats'!C:C) -> 8.2666667 | H27: =_xlfn.XLOOKUP(C27,'Player Stats'!A:A,'Player Stats'!D:D) -> 3.4 | I27: =_xlfn.XLOOKUP(C27,'Player Stats'!A:A,'Player Stats'!E:E) -> 3.2666667 | J27: =_xlfn.XLOOKUP(C27,'Player Stats'!A:A,'Player Stats'!F:F) -> 0.8 | K27: =_xlfn.XLOOKUP(C27,'Player Stats'!A:A,'Player Stats'!G:G) -> 0.26666667 | L27: =_xlfn.XLOOKUP(C27,'Player Stats'!A:A,'Player Stats'!H:H) -> 23.921111 | M27: =F27*G27 -> 124 | N27: =F27*H27 -> 51 | O27: =F27*I27 -> 49 | P27: =F27*J27 -> 12 | Q27: =F27*K27 -> 4 | R27: =F27*L27 -> 358.81667 | S27: =(M27/D27)*1000000 -> 584.50864 | T27: =(N27/D27)*1000000 -> 240.40275 | U27: =(O27/D27)*1000000 -> 230.97519 | V27: =(P27/D27)*1000000 -> 56.565352 | W27: =(Q27/D27)*1000000 -> 18.855117 | X27: =IF(AND(F27>=20,L27>=15),"Yes","No") -> No
A28: 2025-26 | B28: 1194704 | C28: RayJ Dennis | D28: 131903 | E28: Indiana Pacers | F28: =_xlfn.XLOOKUP(C28,'Player Stats'!A:A,'Player Stats'!B:B) -> 17 | G28: =_xlfn.XLOOKUP(C28,'Player Stats'!A:A,'Player Stats'!C:C) -> 4.3529412 | H28: =_xlfn.XLOOKUP(C28,'Player Stats'!A:A,'Player Stats'!D:D) -> 1.5294118 | I28: =_xlfn.XLOOKUP(C28,'Player Stats'!A:A,'Player Stats'!E:E) -> 1.9411765 | J28: =_xlfn.XLOOKUP(C28,'Player Stats'!A:A,'Player Stats'!F:F) -> 0.23529412 | K28: =_xlfn.XLOOKUP(C28,'Player Stats'!A:A,'Player Stats'!G:G) -> 0.23529412 | L28: =_xlfn.XLOOKUP(C28,'Player Stats'!A:A,'Player Stats'!H:H) -> 12.130392 | M28: =F28*G28 -> 74 | N28: =F28*H28 -> 26 | O28: =F28*I28 -> 33 | P28: =F28*J28 -> 4 | Q28: =F28*K28 -> 4 | R28: =F28*L28 -> 206.21667 | S28: =(M28/D28)*1000000 -> 561.01832 | T28: =(N28/D28)*1000000 -> 197.11455 | U28: =(O28/D28)*1000000 -> 250.18385 | V28: =(P28/D28)*1000000 -> 30.325315 | W28: =(Q28/D28)*1000000 -> 30.325315 | X28: =IF(AND(F28>=20,L28>=15),"Yes","No") -> No
A29: 2025-26 | B29: 1343051 | C29: Bez Mbeng | D29: 219459 | E29: Utah Jazz | F29: =_xlfn.XLOOKUP(C29,'Player Stats'!A:A,'Player Stats'!B:B) -> 15 | G29: =_xlfn.XLOOKUP(C29,'Player Stats'!A:A,'Player Stats'!C:C) -> 8.1333333 | H29: =_xlfn.XLOOKUP(C29,'Player Stats'!A:A,'Player Stats'!D:D) -> 3.8 | I29: =_xlfn.XLOOKUP(C29,'Player Stats'!A:A,'Player Stats'!E:E) -> 4.1333333 | J29: =_xlfn.XLOOKUP(C29,'Player Stats'!A:A,'Player Stats'!F:F) -> 2.2666667 | K29: =_xlfn.XLOOKUP(C29,'Player Stats'!A:A,'Player Stats'!G:G) -> 0.33333333 | L29: =_xlfn.XLOOKUP(C29,'Player Stats'!A:A,'Player Stats'!H:H) -> 32.812222 | M29: =F29*G29 -> 122 | N29: =F29*H29 -> 57 | O29: =F29*I29 -> 62 | P29: =F29*J29 -> 34 | Q29: =F29*K29 -> 5 | R29: =F29*L29 -> 492.18333 | S29: =(M29/D29)*1000000 -> 555.91249 | T29: =(N29/D29)*1000000 -> 259.72961 | U29: =(O29/D29)*1000000 -> 282.51291 | V29: =(P29/D29)*1000000 -> 154.92643 | W29: =(Q29/D29)*1000000 -> 22.783299 | X29: =IF(AND(F29>=20,L29>=15),"Yes","No") -> No
A30: 2025-26 | B30: 1458495 | C30: Yves Missi | D30: 3353040 | E30: New Orleans Pelicans | F30: =_xlfn.XLOOKUP(C30,'Player Stats'!A:A,'Player Stats'!B:B) -> 66 | G30: =_xlfn.XLOOKUP(C30,'Player Stats'!A:A,'Player Stats'!C:C) -> 5.7121212 | H30: =_xlfn.XLOOKUP(C30,'Player Stats'!A:A,'Player Stats'!D:D) -> 5.8333333 | I30: =_xlfn.XLOOKUP(C30,'Player Stats'!A:A,'Player Stats'!E:E) -> 1.2727273 | J30: =_xlfn.XLOOKUP(C30,'Player Stats'!A:A,'Player Stats'!F:F) -> 0.3030303 | K30: =_xlfn.XLOOKUP(C30,'Player Stats'!A:A,'Player Stats'!G:G) -> 1.530303 | L30: =_xlfn.XLOOKUP(C30,'Player Stats'!A:A,'Player Stats'!H:H) -> 19.65202 | M30: =F30*G30 -> 377 | N30: =F30*H30 -> 385 | O30: =F30*I30 -> 84 | P30: =F30*J30 -> 20 | Q30: =F30*K30 -> 101 | R30: =F30*L30 -> 1297.0333 | S30: =(M30/D30)*1000000 -> 112.43528 | T30: =(N30/D30)*1000000 -> 114.82118 | U30: =(O30/D30)*1000000 -> 25.051893 | V30: =(P30/D30)*1000000 -> 5.9647365 | W30: =(Q30/D30)*1000000 -> 30.121919 | X30: =IF(AND(F30>=20,L30>=15),"Yes","No") -> Yes
A31: 2025-26 | B31: 1328248 | C31: Jahmai Mashack | D31: 476136 | E31: Memphis Grizzlies | F31: =_xlfn.XLOOKUP(C31,'Player Stats'!A:A,'Player Stats'!B:B) -> 31 | G31: =_xlfn.XLOOKUP(C31,'Player Stats'!A:A,'Player Stats'!C:C) -> 6.1935484 | H31: =_xlfn.XLOOKUP(C31,'Player Stats'!A:A,'Player Stats'!D:D) -> 2.6129032 | I31: =_xlfn.XLOOKUP(C31,'Player Stats'!A:A,'Player Stats'!E:E) -> 2.2258065 | J31: =_xlfn.XLOOKUP(C31,'Player Stats'!A:A,'Player Stats'!F:F) -> 1.1935484 | K31: =_xlfn.XLOOKUP(C31,'Player Stats'!A:A,'Player Stats'!G:G) -> 0.4516129 | L31: =_xlfn.XLOOKUP(C31,'Player Stats'!A:A,'Player Stats'!H:H) -> 21.713978 | M31: =F31*G31 -> 192 | N31: =F31*H31 -> 81 | O31: =F31*I31 -> 69 | P31: =F31*J31 -> 37 | Q31: =F31*K31 -> 14 | R31: =F31*L31 -> 673.13333 | S31: =(M31/D31)*1000000 -> 403.24613 | T31: =(N31/D31)*1000000 -> 170.11946 | U31: =(O31/D31)*1000000 -> 144.91658 | V31: =(P31/D31)*1000000 -> 77.70889 | W31: =(Q31/D31)*1000000 -> 29.403364 | X31: =IF(AND(F31>=20,L31>=15),"Yes","No") -> Yes
A32: 2025-26 | B32: 697720 | C32: Kyle Anderson | D32: 898095 | E32: Minnesota Timberwolves | F32: =_xlfn.XLOOKUP(C32,'Player Stats'!A:A,'Player Stats'!B:B) -> 51 | G32: =_xlfn.XLOOKUP(C32,'Player Stats'!A:A,'Player Stats'!C:C) -> 5.5098039 | H32: =_xlfn.XLOOKUP(C32,'Player Stats'!A:A,'Player Stats'!D:D) -> 3.0784314 | I32: =_xlfn.XLOOKUP(C32,'Player Stats'!A:A,'Player Stats'!E:E) -> 2.7647059 | J32: =_xlfn.XLOOKUP(C32,'Player Stats'!A:A,'Player Stats'!F:F) -> 0.92156863 | K32: =_xlfn.XLOOKUP(C32,'Player Stats'!A:A,'Player Stats'!G:G) -> 0.50980392 | L32: =_xlfn.XLOOKUP(C32,'Player Stats'!A:A,'Player Stats'!H:H) -> 17.923203 | M32: =F32*G32 -> 281 | N32: =F32*H32 -> 157 | O32: =F32*I32 -> 141 | P32: =F32*J32 -> 47 | Q32: =F32*K32 -> 26 | R32: =F32*L32 -> 914.08333 | S32: =(M32/D32)*1000000 -> 312.88449 | T32: =(N32/D32)*1000000 -> 174.81447 | U32: =(O32/D32)*1000000 -> 156.99898 | V32: =(P32/D32)*1000000 -> 52.332994 | W32: =(Q32/D32)*1000000 -> 28.950167 | X32: =IF(AND(F32>=20,L32>=15),"Yes","No") -> Yes
A33: 2025-26 | B33: 1234814 | C33: Chris Youngblood | D33: 131903 | E33: Portland Trail Blazers | F33: =_xlfn.XLOOKUP(C33,'Player Stats'!A:A,'Player Stats'!B:B) -> 34 | G33: =_xlfn.XLOOKUP(C33,'Player Stats'!A:A,'Player Stats'!C:C) -> 2.0882353 | H33: =_xlfn.XLOOKUP(C33,'Player Stats'!A:A,'Player Stats'!D:D) -> 0.82352941 | I33: =_xlfn.XLOOKUP(C33,'Player Stats'!A:A,'Player Stats'!E:E) -> 0.35294118 | J33: =_xlfn.XLOOKUP(C33,'Player Stats'!A:A,'Player Stats'!F:F) -> 0.11764706 | K33: =_xlfn.XLOOKUP(C33,'Player Stats'!A:A,'Player Stats'!G:G) -> 0.088235294 | L33: =_xlfn.XLOOKUP(C33,'Player Stats'!A:A,'Player Stats'!H:H) -> 5.4441176 | M33: =F33*G33 -> 71 | N33: =F33*H33 -> 28 | O33: =F33*I33 -> 12 | P33: =F33*J33 -> 4 | Q33: =F33*K33 -> 3 | R33: =F33*L33 -> 185.1 | S33: =(M33/D33)*1000000 -> 538.27434 | T33: =(N33/D33)*1000000 -> 212.2772 | U33: =(O33/D33)*1000000 -> 90.975944 | V33: =(P33/D33)*1000000 -> 30.325315 | W33: =(Q33/D33)*1000000 -> 22.743986 | X33: =IF(AND(F33>=20,L33>=15),"Yes","No") -> No
A34: 2025-26 | B34: 1432656 | C34: Sidy Cissoko | D34: 1081951 | E34: Portland Trail Blazers | F34: =_xlfn.XLOOKUP(C34,'Player Stats'!A:A,'Player Stats'!B:B) -> 79 | G34: =_xlfn.XLOOKUP(C34,'Player Stats'!A:A,'Player Stats'!C:C) -> 4.9873418 | H34: =_xlfn.XLOOKUP(C34,'Player Stats'!A:A,'Player Stats'!D:D) -> 2.164557 | I34: =_xlfn.XLOOKUP(C34,'Player Stats'!A:A,'Player Stats'!E:E) -> 1.4050633 | J34: =_xlfn.XLOOKUP(C34,'Player Stats'!A:A,'Player Stats'!F:F) -> 0.70886076 | K34: =_xlfn.XLOOKUP(C34,'Player Stats'!A:A,'Player Stats'!G:G) -> 0.3164557 | L34: =_xlfn.XLOOKUP(C34,'Player Stats'!A:A,'Player Stats'!H:H) -> 18.496414 | M34: =F34*G34 -> 394 | N34: =F34*H34 -> 171 | O34: =F34*I34 -> 111 | P34: =F34*J34 -> 56 | Q34: =F34*K34 -> 25 | R34: =F34*L34 -> 1461.2167 | S34: =(M34/D34)*1000000 -> 364.15697 | T34: =(N34/D34)*1000000 -> 158.04782 | U34: =(O34/D34)*1000000 -> 102.59245 | V34: =(P34/D34)*1000000 -> 51.758351 | W34: =(Q34/D34)*1000000 -> 23.106407 | X34: =IF(AND(F34>=20,L34>=15),"Yes","No") -> Yes
A35: 2025-26 | B35: 1323636 | C35: KJ Simpson | D35: 170508 | E35: Denver Nuggets | F35: =_xlfn.XLOOKUP(C35,'Player Stats'!A:A,'Player Stats'!B:B) -> 20 | G35: =_xlfn.XLOOKUP(C35,'Player Stats'!A:A,'Player Stats'!C:C) -> 4.55 | H35: =_xlfn.XLOOKUP(C35,'Player Stats'!A:A,'Player Stats'!D:D) -> 1.85 | I35: =_xlfn.XLOOKUP(C35,'Player Stats'!A:A,'Player Stats'!E:E) -> 2.15 | J35: =_xlfn.XLOOKUP(C35,'Player Stats'!A:A,'Player Stats'!F:F) -> 0.8 | K35: =_xlfn.XLOOKUP(C35,'Player Stats'!A:A,'Player Stats'!G:G) -> 0 | L35: =_xlfn.XLOOKUP(C35,'Player Stats'!A:A,'Player Stats'!H:H) -> 12.880833 | M35: =F35*G35 -> 91 | N35: =F35*H35 -> 37 | O35: =F35*I35 -> 43 | P35: =F35*J35 -> 16 | Q35: =F35*K35 -> 0 | R35: =F35*L35 -> 257.61667 | S35: =(M35/D35)*1000000 -> 533.6993 | T35: =(N35/D35)*1000000 -> 216.99862 | U35: =(O35/D35)*1000000 -> 252.18758 | V35: =(P35/D35)*1000000 -> 93.837239 | W35: =(Q35/D35)*1000000 -> 0 | X35: =IF(AND(F35>=20,L35>=15),"Yes","No") -> No
A36: 2025-26 | B36: 1501940 | C36: Matas Buzelis | D36: 5455560 | E36: Chicago Bulls | F36: =_xlfn.XLOOKUP(C36,'Player Stats'!A:A,'Player Stats'!B:B) -> 77 | G36: =_xlfn.XLOOKUP(C36,'Player Stats'!A:A,'Player Stats'!C:C) -> 16.25974 | H36: =_xlfn.XLOOKUP(C36,'Player Stats'!A:A,'Player Stats'!D:D) -> 5.8181818 | I36: =_xlfn.XLOOKUP(C36,'Player Stats'!A:A,'Player Stats'!E:E) -> 2.0519481 | J36: =_xlfn.XLOOKUP(C36,'Player Stats'!A:A,'Player Stats'!F:F) -> 0.71428571 | K36: =_xlfn.XLOOKUP(C36,'Player Stats'!A:A,'Player Stats'!G:G) -> 1.5064935 | L36: =_xlfn.XLOOKUP(C36,'Player Stats'!A:A,'Player Stats'!H:H) -> 29.198918 | M36: =F36*G36 -> 1252 | N36: =F36*H36 -> 448 | O36: =F36*I36 -> 158 | P36: =F36*J36 -> 55 | Q36: =F36*K36 -> 116 | R36: =F36*L36 -> 2248.3167 | S36: =(M36/D36)*1000000 -> 229.49065 | T36: =(N36/D36)*1000000 -> 82.118059 | U36: =(O36/D36)*1000000 -> 28.96128 | V36: =(P36/D36)*1000000 -> 10.081458 | W36: =(Q36/D36)*1000000 -> 21.262712 | X36: =IF(AND(F36>=20,L36>=15),"Yes","No") -> Yes
A37: 2025-26 | B37: 1061538 | C37: Ethan Thompson | D37: 431096 | E37: Indiana Pacers | F37: =_xlfn.XLOOKUP(C37,'Player Stats'!A:A,'Player Stats'!B:B) -> 32 | G37: =_xlfn.XLOOKUP(C37,'Player Stats'!A:A,'Player Stats'!C:C) -> 6.96875 | H37: =_xlfn.XLOOKUP(C37,'Player Stats'!A:A,'Player Stats'!D:D) -> 2.15625 | I37: =_xlfn.XLOOKUP(C37,'Player Stats'!A:A,'Player Stats'!E:E) -> 1.78125 | J37: =_xlfn.XLOOKUP(C37,'Player Stats'!A:A,'Player Stats'!F:F) -> 0.625 | K37: =_xlfn.XLOOKUP(C37,'Player Stats'!A:A,'Player Stats'!G:G) -> 0.28125 | L37: =_xlfn.XLOOKUP(C37,'Player Stats'!A:A,'Player Stats'!H:H) -> 20.413542 | M37: =F37*G37 -> 223 | N37: =F37*H37 -> 69 | O37: =F37*I37 -> 57 | P37: =F37*J37 -> 20 | Q37: =F37*K37 -> 9 | R37: =F37*L37 -> 653.23333 | S37: =(M37/D37)*1000000 -> 517.28617 | T37: =(N37/D37)*1000000 -> 160.05716 | U37: =(O37/D37)*1000000 -> 132.22113 | V37: =(P37/D37)*1000000 -> 46.393379 | W37: =(Q37/D37)*1000000 -> 20.87702 | X37: =IF(AND(F37>=20,L37>=15),"Yes","No") -> Yes
A38: 2025-26 | B38: 1373356 | C38: Victor Wembanyama | D38: 13376695 | E38: San Antonio Spurs | F38: =_xlfn.XLOOKUP(C38,'Player Stats'!A:A,'Player Stats'!B:B) -> 87 | G38: =_xlfn.XLOOKUP(C38,'Player Stats'!A:A,'Player Stats'!C:C) -> 24.62069 | H38: =_xlfn.XLOOKUP(C38,'Player Stats'!A:A,'Player Stats'!D:D) -> 11.275862 | I38: =_xlfn.XLOOKUP(C38,'Player Stats'!A:A,'Player Stats'!E:E) -> 2.9770115 | J38: =_xlfn.XLOOKUP(C38,'Player Stats'!A:A,'Player Stats'!F:F) -> 1.0114943 | K38: =_xlfn.XLOOKUP(C38,'Player Stats'!A:A,'Player Stats'!G:G) -> 3.183908 | L38: =_xlfn.XLOOKUP(C38,'Player Stats'!A:A,'Player Stats'!H:H) -> 30.355939 | M38: =F38*G38 -> 2142 | N38: =F38*H38 -> 981 | O38: =F38*I38 -> 259 | P38: =F38*J38 -> 88 | Q38: =F38*K38 -> 277 | R38: =F38*L38 -> 2640.9667 | S38: =(M38/D38)*1000000 -> 160.12924 | T38: =(N38/D38)*1000000 -> 73.336501 | U38: =(O38/D38)*1000000 -> 19.362032 | V38: =(P38/D38)*1000000 -> 6.5786056 | W38: =(Q38/D38)*1000000 -> 20.707656 | X38: =IF(AND(F38>=20,L38>=15),"Yes","No") -> Yes
A39: 2025-26 | B39: 1231210 | C39: Keon Ellis | D39: 2301587 | E39: Cleveland Cavaliers | F39: =_xlfn.XLOOKUP(C39,'Player Stats'!A:A,'Player Stats'!B:B) -> 84 | G39: =_xlfn.XLOOKUP(C39,'Player Stats'!A:A,'Player Stats'!C:C) -> 5.9404762 | H39: =_xlfn.XLOOKUP(C39,'Player Stats'!A:A,'Player Stats'!D:D) -> 1.7738095 | I39: =_xlfn.XLOOKUP(C39,'Player Stats'!A:A,'Player Stats'!E:E) -> 0.89285714 | J39: =_xlfn.XLOOKUP(C39,'Player Stats'!A:A,'Player Stats'!F:F) -> 1.0714286 | K39: =_xlfn.XLOOKUP(C39,'Player Stats'!A:A,'Player Stats'!G:G) -> 0.55952381 | L39: =_xlfn.XLOOKUP(C39,'Player Stats'!A:A,'Player Stats'!H:H) -> 18.66627 | M39: =F39*G39 -> 499 | N39: =F39*H39 -> 149 | O39: =F39*I39 -> 75 | P39: =F39*J39 -> 90 | Q39: =F39*K39 -> 47 | R39: =F39*L39 -> 1567.9667 | S39: =(M39/D39)*1000000 -> 216.80692 | T39: =(N39/D39)*1000000 -> 64.73794 | U39: =(O39/D39)*1000000 -> 32.586211 | V39: =(P39/D39)*1000000 -> 39.103453 | W39: =(Q39/D39)*1000000 -> 20.420692 | X39: =IF(AND(F39>=20,L39>=15),"Yes","No") -> Yes
... A44: 2025-26 | B44: 1405867 | C44: Donovan Clingan | D44: 7178400 | E44: Portland Trail Blazers | F44: =_xlfn.XLOOKUP(C44,'Player Stats'!A:A,'Player Stats'!B:B) -> 83 | G44: =_xlfn.XLOOKUP(C44,'Player Stats'!A:A,'Player Stats'!C:C) -> 11.698795 | H44: =_xlfn.XLOOKUP(C44,'Player Stats'!A:A,'Player Stats'!D:D) -> 11.349398 | I44: =_xlfn.XLOOKUP(C44,'Player Stats'!A:A,'Player Stats'!E:E) -> 2.1325301 | J44: =_xlfn.XLOOKUP(C44,'Player Stats'!A:A,'Player Stats'!F:F) -> 0.55421687 | K44: =_xlfn.XLOOKUP(C44,'Player Stats'!A:A,'Player Stats'!G:G) -> 1.6385542 | L44: =_xlfn.XLOOKUP(C44,'Player Stats'!A:A,'Player Stats'!H:H) -> 26.857831 | M44: =F44*G44 -> 971 | N44: =F44*H44 -> 942 | O44: =F44*I44 -> 177 | P44: =F44*J44 -> 46 | Q44: =F44*K44 -> 136 | R44: =F44*L44 -> 2229.2 | S44: =(M44/D44)*1000000 -> 135.26691 | T44: =(N44/D44)*1000000 -> 131.22701 | U44: =(O44/D44)*1000000 -> 24.657305 | V44: =(P44/D44)*1000000 -> 6.4081132 | W44: =(Q44/D44)*1000000 -> 18.945726 | X44: =IF(AND(F44>=20,L44>=15),"Yes","No") -> Yes
...

Sheet VORP Data
A1: Player | B1: Clean_Player | C1: Regular_VORP | D1: Playoff_VORP | E1: D = Combined_VORP
A2: Nikola Jokić | B2: =TRIM(SUBSTITUTE(SUBSTITUTE(SUBSTITUTE(SUBSTITUTE(SUBSTITUTE(SUBSTITUTE(SUBSTITUTE(SUBSTITUTE(SUBSTITUTE(SUBSTITUTE(SUBSTITUTE(SUBSTITUTE(SUBSTITUTE(SUBSTITUTE(SUBSTITUTE(SUBSTITUTE(SUBSTITUTE(SUBSTITUTE(SUBSTITUTE(A2,"ć","c"),"č","c"),"š","s"),"Š","S"),"ž","z"),"ñ","n"),"ü","u"),"í","i"),"é","e"),"ó","o"),"á","a"),"ņ","n"),"ģ","g"),"Ş","S"),"ş","s"),"ū","u"),"ë","e"),"ö","o"),"ä","a")) -> Nikola Jokic | C2: 9.2 | D2: =_xlfn.XLOOKUP(A2,'Playoff VORP'!A:A,'Playoff VORP'!B:B,0) -> 0.6 | E2: =C2+D2 -> 9.8 | F2: =IF(COUNTIF(Analysis!$C:$C,B2)>0,"Matched","NO MATCH") -> Matched
A3: Shai Gilgeous-Alexander | B3: =TRIM(SUBSTITUTE(SUBSTITUTE(SUBSTITUTE(SUBSTITUTE(SUBSTITUTE(SUBSTITUTE(SUBSTITUTE(SUBSTITUTE(SUBSTITUTE(SUBSTITUTE(SUBSTITUTE(SUBSTITUTE(SUBSTITUTE(SUBSTITUTE(SUBSTITUTE(SUBSTITUTE(SUBSTITUTE(SUBSTITUTE(SUBSTITUTE(A3,"ć","c"),"č","c"),"š","s"),"Š","S"),"ž","z"),"ñ","n"),"ü","u"),"í","i"),"é","e"),"ó","o"),"á","a"),"ņ","n"),"ģ","g"),"Ş","S"),"ş","s"),"ū","u"),"ë","e"),"ö","o"),"ä","a")) -> Shai Gilgeous-Alexander | C3: 7.8 | D3: =_xlfn.XLOOKUP(A3,'Playoff VORP'!A:A,'Playoff VORP'!B:B,0) -> 1.2 | E3: =C3+D3 -> 9 | F3: =IF(COUNTIF(Analysis!$C:$C,B3)>0,"Matched","NO MATCH") -> Matched
A4: Luka Dončić | B4: =TRIM(SUBSTITUTE(SUBSTITUTE(SUBSTITUTE(SUBSTITUTE(SUBSTITUTE(SUBSTITUTE(SUBSTITUTE(SUBSTITUTE(SUBSTITUTE(SUBSTITUTE(SUBSTITUTE(SUBSTITUTE(SUBSTITUTE(SUBSTITUTE(SUBSTITUTE(SUBSTITUTE(SUBSTITUTE(SUBSTITUTE(SUBSTITUTE(A4,"ć","c"),"č","c"),"š","s"),"Š","S"),"ž","z"),"ñ","n"),"ü","u"),"í","i"),"é","e"),"ó","o"),"á","a"),"ņ","n"),"ģ","g"),"Ş","S"),"ş","s"),"ū","u"),"ë","e"),"ö","o"),"ä","a")) -> Luka Doncic | C4: 6.6 | D4: =_xlfn.XLOOKUP(A4,'Playoff VORP'!A:A,'Playoff VORP'!B:B,0) -> 0 | E4: =C4+D4 -> 6.6 | F4: =IF(COUNTIF(Analysis!$C:$C,B4)>0,"Matched","NO MATCH") -> Matched
A5: Victor Wembanyama | B5: =TRIM(SUBSTITUTE(SUBSTITUTE(SUBSTITUTE(SUBSTITUTE(SUBSTITUTE(SUBSTITUTE(SUBSTITUTE(SUBSTITUTE(SUBSTITUTE(SUBSTITUTE(SUBSTITUTE(SUBSTITUTE(SUBSTITUTE(SUBSTITUTE(SUBSTITUTE(SUBSTITUTE(SUBSTITUTE(SUBSTITUTE(SUBSTITUTE(A5,"ć","c"),"č","c"),"š","s"),"Š","S"),"ž","z"),"ñ","n"),"ü","u"),"í","i"),"é","e"),"ó","o"),"á","a"),"ņ","n"),"ģ","g"),"Ş","S"),"ş","s"),"ū","u"),"ë","e"),"ö","o"),"ä","a")) -> Victor Wembanyama | C5: 6 | D5: =_xlfn.XLOOKUP(A5,'Playoff VORP'!A:A,'Playoff VORP'!B:B,0) -> 2 | E5: =C5+D5 -> 8 | F5: =IF(COUNTIF(Analysis!$C:$C,B5)>0,"Matched","NO MATCH") -> Matched
A6: Kawhi Leonard | B6: =TRIM(SUBSTITUTE(SUBSTITUTE(SUBSTITUTE(SUBSTITUTE(SUBSTITUTE(SUBSTITUTE(SUBSTITUTE(SUBSTITUTE(SUBSTITUTE(SUBSTITUTE(SUBSTITUTE(SUBSTITUTE(SUBSTITUTE(SUBSTITUTE(SUBSTITUTE(SUBSTITUTE(SUBSTITUTE(SUBSTITUTE(SUBSTITUTE(A6,"ć","c"),"č","c"),"š","s"),"Š","S"),"ž","z"),"ñ","n"),"ü","u"),"í","i"),"é","e"),"ó","o"),"á","a"),"ņ","n"),"ģ","g"),"Ş","S"),"ş","s"),"ū","u"),"ë","e"),"ö","o"),"ä","a")) -> Kawhi Leonard | C6: 5.3 | D6: =_xlfn.XLOOKUP(A6,'Playoff VORP'!A:A,'Playoff VORP'!B:B,0) -> 0 | E6: =C6+D6 -> 5.3 | F6: =IF(COUNTIF(Analysis!$C:$C,B6)>0,"Matched","NO MATCH") -> Matched
A7: Tyrese Maxey | B7: =TRIM(SUBSTITUTE(SUBSTITUTE(SUBSTITUTE(SUBSTITUTE(SUBSTITUTE(SUBSTITUTE(SUBSTITUTE(SUBSTITUTE(SUBSTITUTE(SUBSTITUTE(SUBSTITUTE(SUBSTITUTE(SUBSTITUTE(SUBSTITUTE(SUBSTITUTE(SUBSTITUTE(SUBSTITUTE(SUBSTITUTE(SUBSTITUTE(A7,"ć","c"),"č","c"),"š","s"),"Š","S"),"ž","z"),"ñ","n"),"ü","u"),"í","i"),"é","e"),"ó","o"),"á","a"),"ņ","n"),"ģ","g"),"Ş","S"),"ş","s"),"ū","u"),"ë","e"),"ö","o"),"ä","a")) -> Tyrese Maxey | C7: 4.9 | D7: =_xlfn.XLOOKUP(A7,'Playoff VORP'!A:A,'Playoff VORP'!B:B,0) -> 0.5 | E7: =C7+D7 -> 5.4 | F7: =IF(COUNTIF(Analysis!$C:$C,B7)>0,"Matched","NO MATCH") -> Matched
A8: Kevin Durant | B8: =TRIM(SUBSTITUTE(SUBSTITUTE(SUBSTITUTE(SUBSTITUTE(SUBSTITUTE(SUBSTITUTE(SUBSTITUTE(SUBSTITUTE(SUBSTITUTE(SUBSTITUTE(SUBSTITUTE(SUBSTITUTE(SUBSTITUTE(SUBSTITUTE(SUBSTITUTE(SUBSTITUTE(SUBSTITUTE(SUBSTITUTE(SUBSTITUTE(A8,"ć","c"),"č","c"),"š","s"),"Š","S"),"ž","z"),"ñ","n"),"ü","u"),"í","i"),"é","e"),"ó","o"),"á","a"),"ņ","n"),"ģ","g"),"Ş","S"),"ş","s"),"ū","u"),"ë","e"),"ö","o"),"ä","a")) -> Kevin Durant | C8: 4.7 | D8: =_xlfn.XLOOKUP(A8,'Playoff VORP'!A:A,'Playoff VORP'!B:B,0) -> 0 | E8: =C8+D8 -> 4.7 | F8: =IF(COUNTIF(Analysis!$C:$C,B8)>0,"Matched","NO MATCH") -> Matched
